Traceback (most recent call last):
  File "/usr/local/lib/python3.10/site-packages/jupyter_cache/executors/utils.py", line 58, in single_nb_execution
    executenb(
  File "/usr/local/lib/python3.10/site-packages/nbclient/client.py", line 1314, in execute
    return NotebookClient(nb=nb, resources=resources, km=km, **kwargs).execute()
  File "/usr/local/lib/python3.10/site-packages/jupyter_core/utils/__init__.py", line 165, in wrapped
    return loop.run_until_complete(inner)
  File "/usr/local/Cellar/python@3.10/3.10.13_2/Frameworks/Python.framework/Versions/3.10/lib/python3.10/asyncio/base_events.py", line 649, in run_until_complete
    return future.result()
  File "/usr/local/lib/python3.10/site-packages/nbclient/client.py", line 709, in async_execute
    await self.async_execute_cell(
  File "/usr/local/lib/python3.10/site-packages/nbclient/client.py", line 1062, in async_execute_cell
    await self._check_raise_for_error(cell, cell_index, exec_reply)
  File "/usr/local/lib/python3.10/site-packages/nbclient/client.py", line 918, in _check_raise_for_error
    raise CellExecutionError.from_cell_and_msg(cell, exec_reply_content)
nbclient.exceptions.CellExecutionError: An error occurred while executing the following cell:
------------------
import pandas as pd
import matplotlib.pyplot as plt

# Lecture des donn√©es √† partir des fichiers CSV
pic1_data = pd.read_csv('pic1.csv')
pic2_data = pd.read_csv('pic2.csv')
pic3_data = pd.read_csv('pic3.csv')
pic_inconnu_data = pd.read_csv('pic_inconnu.csv')

# Extraction des valeurs de vitesse
pic1_speed = pic1_data['mesures']
pic2_speed = pic2_data['mesures']
pic3_speed = pic3_data['mesures']
pic_inconnu_speed = pic_inconnu_data['mesures']

# Trac√© des histogrammes
plt.hist(pic1_speed, bins=30, alpha=0.5, label='Vitesse 13.9 m/s')
plt.hist(pic2_speed, bins=30, alpha=0.5, label='Vitesse 19.4 m/s')
plt.hist(pic3_speed, bins=30, alpha=0.5, label='Vitesse 36.1 m/s')
plt.hist(pic_inconnu_speed, bins=30, alpha=0.5, label='Vitesse 36.1 m/s')

plt.xlabel('Vitesse')
plt.ylabel('Fr√©quence')
plt.title('Distribution des vitesses mesur√©es')
plt.legend()

plt.show()

------------------


[0;31m---------------------------------------------------------------------------[0m
[0;31mModuleNotFoundError[0m                       Traceback (most recent call last)
Cell [0;32mIn[1], line 1[0m
[0;32m----> 1[0m [38;5;28;01mimport[39;00m [38;5;21;01mpandas[39;00m [38;5;28;01mas[39;00m [38;5;21;01mpd[39;00m
[1;32m      2[0m [38;5;28;01mimport[39;00m [38;5;21;01mmatplotlib[39;00m[38;5;21;01m.[39;00m[38;5;21;01mpyplot[39;00m [38;5;28;01mas[39;00m [38;5;21;01mplt[39;00m
[1;32m      4[0m [38;5;66;03m# Lecture des donn√©es √† partir des fichiers CSV[39;00m

[0;31mModuleNotFoundError[0m: No module named 'pandas'

