Traceback (most recent call last):
  File "/usr/local/lib/python3.10/site-packages/jupyter_cache/executors/utils.py", line 58, in single_nb_execution
    executenb(
  File "/usr/local/lib/python3.10/site-packages/nbclient/client.py", line 1314, in execute
    return NotebookClient(nb=nb, resources=resources, km=km, **kwargs).execute()
  File "/usr/local/lib/python3.10/site-packages/jupyter_core/utils/__init__.py", line 165, in wrapped
    return loop.run_until_complete(inner)
  File "/usr/local/Cellar/python@3.10/3.10.13_2/Frameworks/Python.framework/Versions/3.10/lib/python3.10/asyncio/base_events.py", line 649, in run_until_complete
    return future.result()
  File "/usr/local/lib/python3.10/site-packages/nbclient/client.py", line 709, in async_execute
    await self.async_execute_cell(
  File "/usr/local/lib/python3.10/site-packages/nbclient/client.py", line 1062, in async_execute_cell
    await self._check_raise_for_error(cell, cell_index, exec_reply)
  File "/usr/local/lib/python3.10/site-packages/nbclient/client.py", line 918, in _check_raise_for_error
    raise CellExecutionError.from_cell_and_msg(cell, exec_reply_content)
nbclient.exceptions.CellExecutionError: An error occurred while executing the following cell:
------------------
# ahora con vals diferentes

# angulo
t = np.linspace(0, 2.*np.pi, 100) # s
th = 0
th = w * t + th_0 # rad

------------------


[0;31m---------------------------------------------------------------------------[0m
[0;31mNameError[0m                                 Traceback (most recent call last)
Cell [0;32mIn[6], line 6[0m
[1;32m      4[0m t [38;5;241m=[39m np[38;5;241m.[39mlinspace([38;5;241m0[39m, [38;5;241m2.[39m[38;5;241m*[39mnp[38;5;241m.[39mpi, [38;5;241m100[39m) [38;5;66;03m# s[39;00m
[1;32m      5[0m th [38;5;241m=[39m [38;5;241m0[39m
[0;32m----> 6[0m th [38;5;241m=[39m w [38;5;241m*[39m t [38;5;241m+[39m [43mth_0[49m [38;5;66;03m# rad[39;00m

[0;31mNameError[0m: name 'th_0' is not defined

